{
 "cells": [
  {
   "cell_type": "code",
   "execution_count": 1,
   "id": "c2128020",
   "metadata": {},
   "outputs": [
    {
     "name": "stdout",
     "output_type": "stream",
     "text": [
      "2.1.0\n"
     ]
    }
   ],
   "source": [
    "import matplotlib.pyplot as plt\n",
    "import numpy as np\n",
    "import pandas as pd\n",
    "import seaborn as sns\n",
    "import numpy as np\n",
    "from sklearn import preprocessing\n",
    "\n",
    "import tensorflow as tf\n",
    "from tensorflow import keras\n",
    "from tensorflow.keras import layers, models\n",
    "\n",
    "print(tf.__version__)\n"
   ]
  },
  {
   "cell_type": "code",
   "execution_count": null,
   "id": "c831b274",
   "metadata": {
    "scrolled": false
   },
   "outputs": [
    {
     "name": "stdout",
     "output_type": "stream",
     "text": [
      "181198.04990215265\n"
     ]
    },
    {
     "name": "stderr",
     "output_type": "stream",
     "text": [
      "ERROR:root:Internal Python error in the inspect module.\n",
      "Below is the traceback from this internal error.\n",
      "\n",
      "ERROR:root:Internal Python error in the inspect module.\n",
      "Below is the traceback from this internal error.\n",
      "\n",
      "ERROR:root:Internal Python error in the inspect module.\n",
      "Below is the traceback from this internal error.\n",
      "\n"
     ]
    },
    {
     "name": "stdout",
     "output_type": "stream",
     "text": [
      "Traceback (most recent call last):\n",
      "  File \"C:\\Users\\mv\\anaconda3\\envs\\mLab\\lib\\site-packages\\IPython\\core\\interactiveshell.py\", line 3444, in run_code\n",
      "    exec(code_obj, self.user_global_ns, self.user_ns)\n",
      "  File \"C:\\Users\\mv\\AppData\\Local\\Temp/ipykernel_3560/177461960.py\", line 6, in <module>\n",
      "    print(train_X.columns())\n",
      "TypeError: 'Index' object is not callable\n",
      "\n",
      "During handling of the above exception, another exception occurred:\n",
      "\n",
      "Traceback (most recent call last):\n",
      "  File \"C:\\Users\\mv\\anaconda3\\envs\\mLab\\lib\\site-packages\\IPython\\core\\interactiveshell.py\", line 2064, in showtraceback\n",
      "    stb = value._render_traceback_()\n",
      "AttributeError: 'TypeError' object has no attribute '_render_traceback_'\n",
      "\n",
      "During handling of the above exception, another exception occurred:\n",
      "\n",
      "Traceback (most recent call last):\n",
      "  File \"C:\\Users\\mv\\anaconda3\\envs\\mLab\\lib\\site-packages\\IPython\\core\\ultratb.py\", line 1101, in get_records\n",
      "    return _fixed_getinnerframes(etb, number_of_lines_of_context, tb_offset)\n",
      "  File \"C:\\Users\\mv\\anaconda3\\envs\\mLab\\lib\\site-packages\\IPython\\core\\ultratb.py\", line 248, in wrapped\n",
      "    return f(*args, **kwargs)\n",
      "  File \"C:\\Users\\mv\\anaconda3\\envs\\mLab\\lib\\site-packages\\IPython\\core\\ultratb.py\", line 281, in _fixed_getinnerframes\n",
      "    records = fix_frame_records_filenames(inspect.getinnerframes(etb, context))\n",
      "  File \"C:\\Users\\mv\\anaconda3\\envs\\mLab\\lib\\inspect.py\", line 1502, in getinnerframes\n",
      "    frameinfo = (tb.tb_frame,) + getframeinfo(tb, context)\n",
      "  File \"C:\\Users\\mv\\anaconda3\\envs\\mLab\\lib\\inspect.py\", line 1460, in getframeinfo\n",
      "    filename = getsourcefile(frame) or getfile(frame)\n",
      "  File \"C:\\Users\\mv\\anaconda3\\envs\\mLab\\lib\\inspect.py\", line 696, in getsourcefile\n",
      "    if getattr(getmodule(object, filename), '__loader__', None) is not None:\n",
      "  File \"C:\\Users\\mv\\anaconda3\\envs\\mLab\\lib\\inspect.py\", line 733, in getmodule\n",
      "    if ismodule(module) and hasattr(module, '__file__'):\n",
      "  File \"C:\\Users\\mv\\anaconda3\\envs\\mLab\\lib\\site-packages\\tensorflow\\__init__.py\", line 50, in __getattr__\n",
      "    module = self._load()\n",
      "  File \"C:\\Users\\mv\\anaconda3\\envs\\mLab\\lib\\site-packages\\tensorflow\\__init__.py\", line 44, in _load\n",
      "    module = _importlib.import_module(self.__name__)\n",
      "  File \"C:\\Users\\mv\\anaconda3\\envs\\mLab\\lib\\importlib\\__init__.py\", line 127, in import_module\n",
      "    return _bootstrap._gcd_import(name[level:], package, level)\n",
      "  File \"<frozen importlib._bootstrap>\", line 1006, in _gcd_import\n",
      "  File \"<frozen importlib._bootstrap>\", line 983, in _find_and_load\n",
      "  File \"<frozen importlib._bootstrap>\", line 965, in _find_and_load_unlocked\n",
      "ModuleNotFoundError: No module named 'tensorflow_core.estimator'\n",
      "Traceback (most recent call last):\n",
      "  File \"C:\\Users\\mv\\anaconda3\\envs\\mLab\\lib\\site-packages\\IPython\\core\\interactiveshell.py\", line 3444, in run_code\n",
      "    exec(code_obj, self.user_global_ns, self.user_ns)\n",
      "  File \"C:\\Users\\mv\\AppData\\Local\\Temp/ipykernel_3560/177461960.py\", line 6, in <module>\n",
      "    print(train_X.columns())\n",
      "TypeError: 'Index' object is not callable\n",
      "\n",
      "During handling of the above exception, another exception occurred:\n",
      "\n",
      "Traceback (most recent call last):\n",
      "  File \"C:\\Users\\mv\\anaconda3\\envs\\mLab\\lib\\site-packages\\IPython\\core\\interactiveshell.py\", line 2064, in showtraceback\n",
      "    stb = value._render_traceback_()\n",
      "AttributeError: 'TypeError' object has no attribute '_render_traceback_'\n",
      "\n",
      "During handling of the above exception, another exception occurred:\n",
      "\n",
      "Traceback (most recent call last):\n",
      "  File \"C:\\Users\\mv\\anaconda3\\envs\\mLab\\lib\\site-packages\\IPython\\core\\interactiveshell.py\", line 3364, in run_ast_nodes\n",
      "    if (await self.run_code(code, result,  async_=asy)):\n",
      "  File \"C:\\Users\\mv\\anaconda3\\envs\\mLab\\lib\\site-packages\\IPython\\core\\interactiveshell.py\", line 3461, in run_code\n",
      "    self.showtraceback(running_compiled_code=True)\n",
      "  File \"C:\\Users\\mv\\anaconda3\\envs\\mLab\\lib\\site-packages\\IPython\\core\\interactiveshell.py\", line 2067, in showtraceback\n",
      "    value, tb, tb_offset=tb_offset)\n",
      "  File \"C:\\Users\\mv\\anaconda3\\envs\\mLab\\lib\\site-packages\\IPython\\core\\ultratb.py\", line 1368, in structured_traceback\n",
      "    self, etype, value, tb, tb_offset, number_of_lines_of_context)\n",
      "  File \"C:\\Users\\mv\\anaconda3\\envs\\mLab\\lib\\site-packages\\IPython\\core\\ultratb.py\", line 1268, in structured_traceback\n",
      "    self, etype, value, tb, tb_offset, number_of_lines_of_context\n",
      "  File \"C:\\Users\\mv\\anaconda3\\envs\\mLab\\lib\\site-packages\\IPython\\core\\ultratb.py\", line 1125, in structured_traceback\n",
      "    tb_offset)\n",
      "  File \"C:\\Users\\mv\\anaconda3\\envs\\mLab\\lib\\site-packages\\IPython\\core\\ultratb.py\", line 1082, in format_exception_as_a_whole\n",
      "    last_unique, recursion_repeat = find_recursion(orig_etype, evalue, records)\n",
      "  File \"C:\\Users\\mv\\anaconda3\\envs\\mLab\\lib\\site-packages\\IPython\\core\\ultratb.py\", line 382, in find_recursion\n",
      "    return len(records), 0\n",
      "TypeError: object of type 'NoneType' has no len()\n",
      "\n",
      "During handling of the above exception, another exception occurred:\n",
      "\n",
      "Traceback (most recent call last):\n",
      "  File \"C:\\Users\\mv\\anaconda3\\envs\\mLab\\lib\\site-packages\\IPython\\core\\interactiveshell.py\", line 2064, in showtraceback\n",
      "    stb = value._render_traceback_()\n",
      "AttributeError: 'TypeError' object has no attribute '_render_traceback_'\n",
      "\n",
      "During handling of the above exception, another exception occurred:\n",
      "\n",
      "Traceback (most recent call last):\n",
      "  File \"C:\\Users\\mv\\anaconda3\\envs\\mLab\\lib\\site-packages\\IPython\\core\\ultratb.py\", line 1101, in get_records\n",
      "    return _fixed_getinnerframes(etb, number_of_lines_of_context, tb_offset)\n",
      "  File \"C:\\Users\\mv\\anaconda3\\envs\\mLab\\lib\\site-packages\\IPython\\core\\ultratb.py\", line 248, in wrapped\n",
      "    return f(*args, **kwargs)\n",
      "  File \"C:\\Users\\mv\\anaconda3\\envs\\mLab\\lib\\site-packages\\IPython\\core\\ultratb.py\", line 281, in _fixed_getinnerframes\n",
      "    records = fix_frame_records_filenames(inspect.getinnerframes(etb, context))\n",
      "  File \"C:\\Users\\mv\\anaconda3\\envs\\mLab\\lib\\inspect.py\", line 1502, in getinnerframes\n",
      "    frameinfo = (tb.tb_frame,) + getframeinfo(tb, context)\n",
      "  File \"C:\\Users\\mv\\anaconda3\\envs\\mLab\\lib\\inspect.py\", line 1460, in getframeinfo\n",
      "    filename = getsourcefile(frame) or getfile(frame)\n",
      "  File \"C:\\Users\\mv\\anaconda3\\envs\\mLab\\lib\\inspect.py\", line 696, in getsourcefile\n",
      "    if getattr(getmodule(object, filename), '__loader__', None) is not None:\n",
      "  File \"C:\\Users\\mv\\anaconda3\\envs\\mLab\\lib\\inspect.py\", line 733, in getmodule\n",
      "    if ismodule(module) and hasattr(module, '__file__'):\n",
      "  File \"C:\\Users\\mv\\anaconda3\\envs\\mLab\\lib\\site-packages\\tensorflow\\__init__.py\", line 50, in __getattr__\n",
      "    module = self._load()\n",
      "  File \"C:\\Users\\mv\\anaconda3\\envs\\mLab\\lib\\site-packages\\tensorflow\\__init__.py\", line 44, in _load\n",
      "    module = _importlib.import_module(self.__name__)\n",
      "  File \"C:\\Users\\mv\\anaconda3\\envs\\mLab\\lib\\importlib\\__init__.py\", line 127, in import_module\n",
      "    return _bootstrap._gcd_import(name[level:], package, level)\n",
      "  File \"<frozen importlib._bootstrap>\", line 1006, in _gcd_import\n",
      "  File \"<frozen importlib._bootstrap>\", line 983, in _find_and_load\n",
      "  File \"<frozen importlib._bootstrap>\", line 965, in _find_and_load_unlocked\n",
      "ModuleNotFoundError: No module named 'tensorflow_core.estimator'\n",
      "Traceback (most recent call last):\n",
      "  File \"C:\\Users\\mv\\anaconda3\\envs\\mLab\\lib\\site-packages\\IPython\\core\\interactiveshell.py\", line 3444, in run_code\n",
      "    exec(code_obj, self.user_global_ns, self.user_ns)\n",
      "  File \"C:\\Users\\mv\\AppData\\Local\\Temp/ipykernel_3560/177461960.py\", line 6, in <module>\n",
      "    print(train_X.columns())\n",
      "TypeError: 'Index' object is not callable\n",
      "\n",
      "During handling of the above exception, another exception occurred:\n",
      "\n",
      "Traceback (most recent call last):\n",
      "  File \"C:\\Users\\mv\\anaconda3\\envs\\mLab\\lib\\site-packages\\IPython\\core\\interactiveshell.py\", line 2064, in showtraceback\n",
      "    stb = value._render_traceback_()\n",
      "AttributeError: 'TypeError' object has no attribute '_render_traceback_'\n",
      "\n",
      "During handling of the above exception, another exception occurred:\n",
      "\n",
      "Traceback (most recent call last):\n",
      "  File \"C:\\Users\\mv\\anaconda3\\envs\\mLab\\lib\\site-packages\\IPython\\core\\interactiveshell.py\", line 3364, in run_ast_nodes\n",
      "    if (await self.run_code(code, result,  async_=asy)):\n",
      "  File \"C:\\Users\\mv\\anaconda3\\envs\\mLab\\lib\\site-packages\\IPython\\core\\interactiveshell.py\", line 3461, in run_code\n",
      "    self.showtraceback(running_compiled_code=True)\n",
      "  File \"C:\\Users\\mv\\anaconda3\\envs\\mLab\\lib\\site-packages\\IPython\\core\\interactiveshell.py\", line 2067, in showtraceback\n",
      "    value, tb, tb_offset=tb_offset)\n",
      "  File \"C:\\Users\\mv\\anaconda3\\envs\\mLab\\lib\\site-packages\\IPython\\core\\ultratb.py\", line 1368, in structured_traceback\n",
      "    self, etype, value, tb, tb_offset, number_of_lines_of_context)\n",
      "  File \"C:\\Users\\mv\\anaconda3\\envs\\mLab\\lib\\site-packages\\IPython\\core\\ultratb.py\", line 1268, in structured_traceback\n",
      "    self, etype, value, tb, tb_offset, number_of_lines_of_context\n",
      "  File \"C:\\Users\\mv\\anaconda3\\envs\\mLab\\lib\\site-packages\\IPython\\core\\ultratb.py\", line 1125, in structured_traceback\n",
      "    tb_offset)\n",
      "  File \"C:\\Users\\mv\\anaconda3\\envs\\mLab\\lib\\site-packages\\IPython\\core\\ultratb.py\", line 1082, in format_exception_as_a_whole\n",
      "    last_unique, recursion_repeat = find_recursion(orig_etype, evalue, records)\n",
      "  File \"C:\\Users\\mv\\anaconda3\\envs\\mLab\\lib\\site-packages\\IPython\\core\\ultratb.py\", line 382, in find_recursion\n",
      "    return len(records), 0\n",
      "TypeError: object of type 'NoneType' has no len()\n",
      "\n",
      "During handling of the above exception, another exception occurred:\n",
      "\n",
      "Traceback (most recent call last):\n",
      "  File \"C:\\Users\\mv\\anaconda3\\envs\\mLab\\lib\\site-packages\\IPython\\core\\interactiveshell.py\", line 2064, in showtraceback\n",
      "    stb = value._render_traceback_()\n",
      "AttributeError: 'TypeError' object has no attribute '_render_traceback_'\n",
      "\n",
      "During handling of the above exception, another exception occurred:\n",
      "\n",
      "Traceback (most recent call last):\n",
      "  File \"C:\\Users\\mv\\anaconda3\\envs\\mLab\\lib\\site-packages\\IPython\\core\\interactiveshell.py\", line 2947, in _run_cell\n",
      "    return runner(coro)\n",
      "  File \"C:\\Users\\mv\\anaconda3\\envs\\mLab\\lib\\site-packages\\IPython\\core\\async_helpers.py\", line 68, in _pseudo_sync_runner\n",
      "    coro.send(None)\n",
      "  File \"C:\\Users\\mv\\anaconda3\\envs\\mLab\\lib\\site-packages\\IPython\\core\\interactiveshell.py\", line 3173, in run_cell_async\n",
      "    interactivity=interactivity, compiler=compiler, result=result)\n",
      "  File \"C:\\Users\\mv\\anaconda3\\envs\\mLab\\lib\\site-packages\\IPython\\core\\interactiveshell.py\", line 3383, in run_ast_nodes\n",
      "    self.showtraceback()\n",
      "  File \"C:\\Users\\mv\\anaconda3\\envs\\mLab\\lib\\site-packages\\IPython\\core\\interactiveshell.py\", line 2067, in showtraceback\n",
      "    value, tb, tb_offset=tb_offset)\n",
      "  File \"C:\\Users\\mv\\anaconda3\\envs\\mLab\\lib\\site-packages\\IPython\\core\\ultratb.py\", line 1368, in structured_traceback\n",
      "    self, etype, value, tb, tb_offset, number_of_lines_of_context)\n",
      "  File \"C:\\Users\\mv\\anaconda3\\envs\\mLab\\lib\\site-packages\\IPython\\core\\ultratb.py\", line 1268, in structured_traceback\n",
      "    self, etype, value, tb, tb_offset, number_of_lines_of_context\n",
      "  File \"C:\\Users\\mv\\anaconda3\\envs\\mLab\\lib\\site-packages\\IPython\\core\\ultratb.py\", line 1143, in structured_traceback\n",
      "    chained_exceptions_tb_offset)\n",
      "  File \"C:\\Users\\mv\\anaconda3\\envs\\mLab\\lib\\site-packages\\IPython\\core\\ultratb.py\", line 1082, in format_exception_as_a_whole\n",
      "    last_unique, recursion_repeat = find_recursion(orig_etype, evalue, records)\n",
      "  File \"C:\\Users\\mv\\anaconda3\\envs\\mLab\\lib\\site-packages\\IPython\\core\\ultratb.py\", line 382, in find_recursion\n",
      "    return len(records), 0\n",
      "TypeError: object of type 'NoneType' has no len()\n",
      "\n",
      "During handling of the above exception, another exception occurred:\n",
      "\n",
      "Traceback (most recent call last):\n",
      "  File \"C:\\Users\\mv\\anaconda3\\envs\\mLab\\lib\\site-packages\\IPython\\core\\interactiveshell.py\", line 2064, in showtraceback\n",
      "    stb = value._render_traceback_()\n",
      "AttributeError: 'TypeError' object has no attribute '_render_traceback_'\n",
      "\n",
      "During handling of the above exception, another exception occurred:\n",
      "\n",
      "Traceback (most recent call last):\n",
      "  File \"C:\\Users\\mv\\anaconda3\\envs\\mLab\\lib\\site-packages\\IPython\\core\\ultratb.py\", line 1101, in get_records\n",
      "    return _fixed_getinnerframes(etb, number_of_lines_of_context, tb_offset)\n",
      "  File \"C:\\Users\\mv\\anaconda3\\envs\\mLab\\lib\\site-packages\\IPython\\core\\ultratb.py\", line 248, in wrapped\n",
      "    return f(*args, **kwargs)\n",
      "  File \"C:\\Users\\mv\\anaconda3\\envs\\mLab\\lib\\site-packages\\IPython\\core\\ultratb.py\", line 281, in _fixed_getinnerframes\n",
      "    records = fix_frame_records_filenames(inspect.getinnerframes(etb, context))\n",
      "  File \"C:\\Users\\mv\\anaconda3\\envs\\mLab\\lib\\inspect.py\", line 1502, in getinnerframes\n",
      "    frameinfo = (tb.tb_frame,) + getframeinfo(tb, context)\n",
      "  File \"C:\\Users\\mv\\anaconda3\\envs\\mLab\\lib\\inspect.py\", line 1460, in getframeinfo\n",
      "    filename = getsourcefile(frame) or getfile(frame)\n",
      "  File \"C:\\Users\\mv\\anaconda3\\envs\\mLab\\lib\\inspect.py\", line 696, in getsourcefile\n",
      "    if getattr(getmodule(object, filename), '__loader__', None) is not None:\n",
      "  File \"C:\\Users\\mv\\anaconda3\\envs\\mLab\\lib\\inspect.py\", line 733, in getmodule\n",
      "    if ismodule(module) and hasattr(module, '__file__'):\n",
      "  File \"C:\\Users\\mv\\anaconda3\\envs\\mLab\\lib\\site-packages\\tensorflow\\__init__.py\", line 50, in __getattr__\n",
      "    module = self._load()\n",
      "  File \"C:\\Users\\mv\\anaconda3\\envs\\mLab\\lib\\site-packages\\tensorflow\\__init__.py\", line 44, in _load\n",
      "    module = _importlib.import_module(self.__name__)\n",
      "  File \"C:\\Users\\mv\\anaconda3\\envs\\mLab\\lib\\importlib\\__init__.py\", line 127, in import_module\n",
      "    return _bootstrap._gcd_import(name[level:], package, level)\n",
      "  File \"<frozen importlib._bootstrap>\", line 1006, in _gcd_import\n",
      "  File \"<frozen importlib._bootstrap>\", line 983, in _find_and_load\n",
      "  File \"<frozen importlib._bootstrap>\", line 965, in _find_and_load_unlocked\n",
      "ModuleNotFoundError: No module named 'tensorflow_core.estimator'\n"
     ]
    }
   ],
   "source": [
    "from data_processing import import_and_clean_train, label_encoding\n",
    "\n",
    "train_X, test_X, train_y, test_y, labels_dict = import_and_clean_train('train', label_encoding)\n",
    "\n",
    "print(train_y.mean())\n",
    "print(train_X.columns())"
   ]
  },
  {
   "cell_type": "code",
   "execution_count": 2,
   "id": "64dad46a",
   "metadata": {},
   "outputs": [
    {
     "name": "stdout",
     "output_type": "stream",
     "text": [
      "ERROR! Session/line number was not unique in database. History logging moved to new session 448\n"
     ]
    }
   ],
   "source": [
    "# Converting the data to arrays\n",
    "train_X = np.array(train_X)\n",
    "train_y = np.array(train_y)\n",
    "test_X = np.array(test_X)\n",
    "test_y = np.array(test_y)"
   ]
  },
  {
   "cell_type": "markdown",
   "id": "7c5adc40",
   "metadata": {},
   "source": [
    "Preprocessing: defining the normalizer and adapting it to the train set:"
   ]
  },
  {
   "cell_type": "code",
   "execution_count": 3,
   "id": "6a7878aa",
   "metadata": {
    "scrolled": true
   },
   "outputs": [],
   "source": [
    "scaler = preprocessing.StandardScaler().fit(train_X)\n",
    "\n",
    "train_X = scaler.transform(train_X)\n",
    "test_X = scaler.transform(test_X)"
   ]
  },
  {
   "cell_type": "markdown",
   "id": "ee843118",
   "metadata": {},
   "source": [
    "Function to plot the loss (mean absolute error) at each epoch:"
   ]
  },
  {
   "cell_type": "code",
   "execution_count": 4,
   "id": "5f947db5",
   "metadata": {},
   "outputs": [],
   "source": [
    "# function used in the train function to plot the cost of the model\n",
    "def plot_loss(history):\n",
    "    plt.plot(history.history['loss'], label='loss')\n",
    "    plt.plot(history.history['val_loss'], label='val_loss')\n",
    "    plt.ylim([0, 200000])\n",
    "    plt.xlabel('Epoch')\n",
    "    plt.ylabel('Error [SalePrice]')\n",
    "    plt.legend()\n",
    "    plt.grid(True)\n",
    "    plt.show()\n",
    "\n",
    "# funtion to plot the prediction of the test data\n",
    "def plot_predictions(model):\n",
    "    test_predictions = model.predict(test_X).flatten()\n",
    "    a = plt.axes(aspect='equal')\n",
    "    plt.scatter(test_y, test_predictions)\n",
    "    plt.xlabel('True Values [SalePrice]')\n",
    "    plt.ylabel('Predictions [SalePrice]')\n",
    "    lims = [0, 500000]\n",
    "    plt.xlim(lims)\n",
    "    plt.ylim(lims)\n",
    "    _ = plt.plot(lims, lims)\n",
    "    plt.show()\n",
    "\n",
    "# funtion to plot the error distribution of the model\n",
    "def plot_errors(model):\n",
    "    test_predictions = model.predict(test_X).flatten()\n",
    "    error = test_predictions - test_y\n",
    "    plt.hist(error, bins=25)\n",
    "    plt.xlabel('Prediction Error [SalePrice]')\n",
    "    _ = plt.ylabel('Count')\n",
    "    plt.show()\n"
   ]
  },
  {
   "cell_type": "markdown",
   "id": "854c5134",
   "metadata": {},
   "source": [
    "Function to train and evaluate a model which layers are defined outside it:"
   ]
  },
  {
   "cell_type": "code",
   "execution_count": 5,
   "id": "7849ec86",
   "metadata": {
    "scrolled": true
   },
   "outputs": [],
   "source": [
    "def train_and_evaluate(model, train_x, train_y, val_x, val_y, epochs=100):\n",
    "\n",
    "    model.compile(loss='mean_absolute_error', optimizer=tf.keras.optimizers.Adam(0.001))\n",
    "\n",
    "    history = model.fit(x=train_X, y=train_y, validation_data=(val_x, val_y), verbose=0, epochs=epochs)\n",
    "\n",
    "    plot_loss(history)\n",
    "\n",
    "    print(f\"Train loss: {history.history['loss'][-1]}, val_loss {history.history['val_loss'][-1]}\")"
   ]
  },
  {
   "cell_type": "markdown",
   "id": "57f0e46e",
   "metadata": {},
   "source": [
    "Preliminary model:"
   ]
  },
  {
   "cell_type": "code",
   "execution_count": null,
   "id": "db4ad4b8",
   "metadata": {
    "scrolled": true
   },
   "outputs": [],
   "source": [
    "model = models.Sequential()\n",
    "model.add(layers.Dense(67, activation='relu'))\n",
    "\n",
    "\n",
    "# model.add(layers.Dense(268, activation='relu'))\n",
    "# model.add(layers.Dense(268, activation='relu'))\n",
    "# model.add(layers.Dense(134, activation='relu'))\n",
    "\n",
    "# model.add(layers.Dense(67, activation='relu'))\n",
    "# model.add(layers.Dense(33, activation='relu'))\n",
    "# model.add(layers.Dense(17, activation='relu'))\n",
    "\n",
    "model.add(layers.Dense(1))\n",
    "\n",
    "train_and_evaluate(model, train_X, train_y, test_X, test_y, epochs=700)"
   ]
  },
  {
   "cell_type": "code",
   "execution_count": null,
   "id": "57c52ab6",
   "metadata": {},
   "outputs": [],
   "source": [
    "# Plotting the predictions of the test data based on the model\n",
    "plot_predictions(model)\n",
    "plot_errors(model)"
   ]
  },
  {
   "cell_type": "markdown",
   "id": "4aaabb5e",
   "metadata": {},
   "source": [
    "Models for experimentation based on the architecture of the preliminary model:"
   ]
  },
  {
   "cell_type": "code",
   "execution_count": null,
   "id": "b9bc7d74",
   "metadata": {},
   "outputs": [],
   "source": [
    "model = models.Sequential()\n",
    "model.add(layers.Dense(67, activation='relu'))\n",
    "# model.add(layers.BatchNormalization())\n",
    "# model.add(layers.Dropout(.2))\n",
    "\n",
    "model.add(layers.Dense(268, activation='relu'))\n",
    "model.add(layers.BatchNormalization())\n",
    "# model.add(layers.Dropout(.2))\n",
    "\n",
    "model.add(layers.Dense(268, activation='relu'))\n",
    "model.add(layers.BatchNormalization())\n",
    "# model.add(layers.Dropout(.2))\n",
    "\n",
    "model.add(layers.Dense(134, activation='relu'))\n",
    "# model.add(layers.BatchNormalization())\n",
    "# model.add(layers.Dropout(.2))\n",
    "\n",
    "model.add(layers.Dense(67, activation='relu'))\n",
    "# model.add(layers.Dense(33, activation='relu'))\n",
    "# model.add(layers.Dense(17, activation='relu'))\n",
    "\n",
    "\n",
    "model.add(layers.Dense(1))\n",
    "\n",
    "train_and_evaluate(model, train_X, train_y, test_X, test_y, epochs=700)"
   ]
  },
  {
   "cell_type": "code",
   "execution_count": null,
   "id": "a7181aec",
   "metadata": {},
   "outputs": [],
   "source": [
    "model = models.Sequential()\n",
    "model.add(layers.Dense(67, activation='relu'))\n",
    "# model.add(layers.BatchNormalization())\n",
    "\n",
    "model.add(layers.Dense(268, activation='relu'))\n",
    "# model.add(layers.BatchNormalization())\n",
    "\n",
    "model.add(layers.Dense(268, activation='relu'))\n",
    "# model.add(layers.BatchNormalization())\n",
    "model.add(layers.Dropout(.3))\n",
    "\n",
    "model.add(layers.Dense(134, activation='relu'))\n",
    "# model.add(layers.BatchNormalization())\n",
    "# model.add(layers.Dropout(.5))\n",
    "\n",
    "model.add(layers.Dense(67, activation='relu'))\n",
    "# model.add(layers.Dense(33, activation='relu'))\n",
    "# model.add(layers.Dense(17, activation='relu'))\n",
    "\n",
    "\n",
    "model.add(layers.Dense(1))\n",
    "\n",
    "train_and_evaluate(model, train_X, train_y, test_X, test_y, epochs=400)"
   ]
  },
  {
   "cell_type": "code",
   "execution_count": null,
   "id": "996015c5",
   "metadata": {},
   "outputs": [],
   "source": []
  }
 ],
 "metadata": {
  "kernelspec": {
   "display_name": "Python 3 (ipykernel)",
   "language": "python",
   "name": "python3"
  },
  "language_info": {
   "codemirror_mode": {
    "name": "ipython",
    "version": 3
   },
   "file_extension": ".py",
   "mimetype": "text/x-python",
   "name": "python",
   "nbconvert_exporter": "python",
   "pygments_lexer": "ipython3",
   "version": "3.7.11"
  }
 },
 "nbformat": 4,
 "nbformat_minor": 5
}
